<?xml version='1.0'?>
<ns2:test-suite xmlns:ns2='urn:model.allure.qatools.yandex.ru' start='1589476246602' stop='1589476338147'>
    <name>Connection</name>
    <title>Connection</title>
    <test-cases>
        <test-case start='1589476246602' status='passed' stop='1589476299097'>
            <name>In-place with Free plan</name>
            <title>In-place with Free plan</title>
            <labels/>
            <parameters/>
            <steps>
                <step start='1589476259541' status='passed' stop='1589476297819'>
                    <name>Can start in-place connection</name>
                    <title>Can start in-place connection</title>
                    <attachments/>
                    <steps/>
                </step>
                <step start='1589476297819' status='passed' stop='1589476298824'>
                    <name>Can assert that site is connected</name>
                    <title>Can assert that site is connected</title>
                    <attachments/>
                    <steps/>
                </step>
            </steps>
            <attachments/>
        </test-case>
        <test-case start='1589476299097' status='failed' stop='1589476331805'>
            <name>In-place upgrading a plan from personal to premium</name>
            <title>In-place upgrading a plan from personal to premium</title>
            <labels/>
            <parameters/>
            <steps>
                <step start='1589476306158' status='undefined'>
                    <name>Can set a sandbox cookie</name>
                    <title>Can set a sandbox cookie</title>
                    <attachments>
                        <attachment title='Test failed: Connection :: In-place upgrading a plan from personal to premium' source='eb9325a3-3afc-42e7-8f19-b8796905b926-attachment.png' type='image/png' size='23773'/>
                    </attachments>
                    <steps/>
                </step>
            </steps>
            <attachments/>
            <failure>
                <message>Error: Command failed: rm /home/travis/wordpress/wp-content/plugins/e2e-plan-data-interceptor.php
                rm: cannot remove ‘/home/travis/wordpress/wp-content/plugins/e2e-plan-data-interceptor.php’: No such file or directory
                </message>
                <stack-trace>Error: Command failed: rm /home/travis/wordpress/wp-content/plugins/e2e-plan-data-interceptor.php
                rm: cannot remove ‘/home/travis/wordpress/wp-content/plugins/e2e-plan-data-interceptor.php’: No such file or directory
                
                    at checkExecSyncError (child_process.js:629:11)
                    at execSync (child_process.js:666:13)
                    at execSyncShellCommand (/home/travis/build/Automattic/jetpack/tests/e2e/lib/utils-helper.js:27:9)
                    at _callee$ (/home/travis/build/Automattic/jetpack/tests/e2e/specs/connection.test.js:36:9)
                    at tryCatch (/home/travis/build/Automattic/jetpack/node_modules/@babel/runtime/node_modules/regenerator-runtime/runtime.js:45:40)
                    at Generator.invoke [as _invoke] (/home/travis/build/Automattic/jetpack/node_modules/@babel/runtime/node_modules/regenerator-runtime/runtime.js:274:22)
                    at Generator.prototype.(anonymous function) [as next] (/home/travis/build/Automattic/jetpack/node_modules/@babel/runtime/node_modules/regenerator-runtime/runtime.js:97:21)
                    at asyncGeneratorStep (/home/travis/build/Automattic/jetpack/node_modules/@babel/runtime/helpers/asyncToGenerator.js:3:24)
                    at _next (/home/travis/build/Automattic/jetpack/node_modules/@babel/runtime/helpers/asyncToGenerator.js:25:9)
                    at process._tickCallback (internal/process/next_tick.js:68:7)</stack-trace>
            </failure>
        </test-case>
    </test-cases>
</ns2:test-suite>